ptOkay, let's dive deep into `noexcept`, starting from the basics.

**1. First Principles: Why Do We Have Exceptions?**

Imagine you're writing code. Sometimes, things go wrong *at runtime* in ways you can't easily predict just by looking at the code:
* You try to open a file, but it doesn't exist.
* You ask for more memory, but the system is out of memory.
* You try to access a web resource, but the network is down.
* You perform a calculation that results in an impossible value (like dividing by zero, though C++ handles this differently).

How do you deal with these errors?

* **Old C style:** Functions often return error codes (like `0`, `-1`, or `nullptr`). The *caller* of the function *must* remember to check this return value immediately. If they forget, the program might proceed with invalid data, leading to crashes or weird behavior later on. This is error-prone.
* **C++ Exceptions:** C++ introduced exceptions as a more robust way to handle runtime errors.
    * When an error occurs, code can `throw` an exception object (which can be of any type, often a class derived from `std::exception`).
    * This immediately interrupts the normal flow of execution.
    * The program goes *backward* up the chain of function calls (this is called **stack unwinding**) looking for a `catch` block that knows how to handle that specific type of exception.
    * As it unwinds, destructors of local objects created within the exited scopes are automatically called, cleaning up resources (this is RAII - Resource Acquisition Is Initialization).
    * If a matching `catch` block is found, execution resumes there.
    * If no `catch` block is found anywhere up the call stack, the special function `std::terminate()` is called, and the program usually aborts.

**Exceptions are powerful but have implications:**

* **Control Flow:** They create hidden paths through your code.
* **Performance:** Compilers need to add extra bookkeeping code to manage potential stack unwinding, even if an exception is never actually thrown. This *can* have a small performance cost.
* **Complexity:** Writing code that behaves correctly even when exceptions occur (exception safety) can be challenging.

**2. Introducing `noexcept`: The Promise**

Sometimes, you write a function, and you *know* it simply cannot fail in a way that would need to throw an exception. Examples:
* Moving data from one object to another (like transferring ownership of a pointer).
* Swapping the contents of two simple variables.
* Basic arithmetic on built-in types.
* Destroying an object (destructors).

In these cases, the potential overhead and complexity added by the *possibility* of exceptions are unnecessary. This is where `noexcept` comes in.

`noexcept` is a **specifier** you add to a function declaration or definition. It's a **promise** you make to the compiler and anyone calling your function:

```cpp
void myFunction() noexcept; // Declaration
void myFunction() noexcept { // Definition
    // ... implementation that guarantees not to throw ...
}
```

**What `noexcept` Guarantees (The Promise):**

* It guarantees that **no C++ exception will propagate out of this function**.
* It does *not* mean errors are impossible *inside* the function. It means if an internal operation *does* throw an exception, that exception *must* be caught and handled *within* the `noexcept` function itself. It cannot be allowed to escape.

**3. Behavior Difference: The Consequence of Breaking the Promise**

This promise is taken very seriously by the C++ standard.

* **Function *without* `noexcept`:** If it throws, the exception propagates up the call stack normally, looking for a `catch` block. Stack unwinding happens.
    ```cpp
    #include <iostream>
    #include <stdexcept>

    void might_throw() { // No noexcept specifier
        std::cout << "might_throw() is running..." << std::endl;
        throw std::runtime_error("Something went wrong!");
        std::cout << "This line is never reached." << std::endl;
    }

    int main() {
        try {
            might_throw();
        } catch (const std::exception& e) {
            std::cout << "Caught exception: " << e.what() << std::endl;
        }
        std::cout << "Program continues normally after catching." << std::endl;
        return 0;
    }
    // Output:
    // might_throw() is running...
    // Caught exception: Something went wrong!
    // Program continues normally after catching.
    ```

* **Function *with* `noexcept`:** If an exception *tries* to escape this function (either thrown directly inside it or by a function it calls), the program does **not** unwind the stack looking for a handler. Instead, `std::terminate()` is called **immediately**. This usually causes the program to abort abruptly.
    ```cpp
    #include <iostream>
    #include <stdexcept>
    #include <cstdlib> // For std::abort often called by std::terminate

    // Promise: This function will not let an exception escape.
    void will_not_throw() noexcept {
        std::cout << "will_not_throw() is running..." << std::endl;
        // OOPS! We broke the promise!
        throw std::runtime_error("This exception will escape!");
        std::cout << "This line is never reached." << std::endl;
    }

    int main() {
        try {
            // Calling a noexcept function that violates its promise
            will_not_throw();
        } catch (const std::exception& e) {
            // This catch block will NEVER be reached because std::terminate
            // is called before stack unwinding gets here.
            std::cout << "Caught exception: " << e.what() << std::endl;
        }
        std::cout << "This line is likely never reached." << std::endl;
        return 0;
    }
    // Output (typical, exact message may vary):
    // will_not_throw() is running...
    // terminate called after throwing an instance of 'std::runtime_error'
    //   what():  This exception will escape!
    // Aborted (core dumped)
    ```

**Why this drastic behavior?** Because `noexcept` allows the compiler and standard library to make significant optimizations based on the *certainty* that no exception will occur. If that certainty is violated, the assumptions are broken, and the only safe thing to do is terminate.

**4. Motivation: Why Do We *Want* `noexcept`?**

* **Performance/Optimization:**
    * **Compiler:** When the compiler sees a call to a `noexcept` function, it knows it doesn't need to generate the extra code associated with potential stack unwinding for that call. This can lead to slightly smaller and faster code.
    * **Standard Library (The Killer Feature!):** Standard library components, especially containers like `std::vector`, can use `noexcept` to choose *more efficient algorithms* while still maintaining safety guarantees.

* **Exception Safety Guarantees:**
    * **Basic Guarantee:** If an operation throws, the object is left in some valid state (no leaks, invariants hold).
    * **Strong Guarantee:** If an operation throws, the object's state is rolled back to *exactly* what it was before the operation started. (Very desirable!)
    * **Nothrow Guarantee:** The operation is guaranteed not to throw. (`noexcept` provides this).

    Let's revisit the `std::vector` reallocation example:
    1.  Vector needs more space.
    2.  Allocates a new, larger memory buffer.
    3.  **Transfers existing elements** from the old buffer to the new one.
    4.  Deallocates the old buffer.

    Now, consider step 3 (transferring elements) and the strong guarantee desired for operations like `push_back`:

    * **If we Copy:** We use the element's copy constructor. If a copy throws an exception halfway through, no problem! The original elements in the old buffer are still untouched. The vector can just delete the new buffer and pretend the reallocation never happened. **Strong Guarantee maintained.** Copying can be slow, though.
    * **If we Move:** We use the element's move constructor. Moving is usually much faster (e.g., just swapping pointers). But what if the move constructor *could* throw? If it throws halfway through moving elements, some elements are now in the new buffer, their original versions in the old buffer are in a *moved-from* (potentially useless) state, and other elements haven't been touched. The vector is now corrupted! Rolling back to the original state is impossible. **Strong Guarantee broken.**
    * **The `noexcept` Solution:** If the element's move constructor is marked `noexcept`, the `std::vector` *knows* it can safely use the fast move operation during reallocation without risking breaking the Strong Guarantee. If the move constructor is *not* `noexcept`, the vector will conservatively fall back to the slower *copy* operation to preserve the guarantee.

    **Therefore, marking move constructors and move assignment operators `noexcept` (when they truly don't throw) is crucial for getting optimal performance from standard containers.**

**5. Guiding Principles: When to Use `noexcept`**

* **Destructors:** Always make destructors `noexcept`. Exceptions escaping from destructors are extremely problematic, especially during stack unwinding caused by *another* exception (it leads straight to `std::terminate`). In C++11 and later, destructors are implicitly `noexcept` unless you explicitly state otherwise or unless a member/base class has a potentially throwing destructor. Be explicit if needed: `~MyClass() noexcept;`
* **Move Operations:** Mark move constructors and move assignment operators `noexcept` *if they genuinely do not throw*. This is usually the case as they should ideally just transfer ownership of resources (e.g., pointers, handles) and modify basic members. This unlocks container optimizations.
    ```cpp
    class ResourceManager {
        int* data = nullptr;
    public:
        // ... constructors, destructor, etc. ...

        // Move constructor: Just transfers pointer ownership. No allocation, no I/O. Safe.
        ResourceManager(ResourceManager&& other) noexcept
          : data(other.data) // Steal the pointer
        {
            other.data = nullptr; // Leave the source empty
        }

        // Move assignment: Similar logic. Needs check for self-assignment.
        ResourceManager& operator=(ResourceManager&& other) noexcept {
            if (this != &other) { // Prevent self-assignment
                 delete data; // Release our own resource first
                 data = other.data; // Steal the other's pointer
                 other.data = nullptr; // Leave the source empty
            }
            return *this;
        }
    };
    ```
* **Swap Functions:** Custom `swap` functions are often implemented using moves and should generally be `noexcept`. `std::swap` itself is `noexcept` if the underlying move operations are `noexcept`.
* **Low-level/Simple Functions:** Functions that only perform basic operations known not to throw (arithmetic on built-ins, non-allocating data structure manipulation, bit-fiddling) are good candidates.
* **When NOT to use `noexcept`:** If your function *needs* to signal failure and the natural way to do that is via an exception (e.g., memory allocation with `new`, file I/O, network calls, calling other functions that might throw), then **do not** mark it `noexcept`. Lying to the compiler by marking a potentially throwing function `noexcept` leads to `std::terminate`.

**In essence: Use `noexcept` when you can genuinely guarantee the function will not let an exception escape, especially for destructors and move operations to gain safety and performance benefits.** Don't use it just because you *hope* an exception won't happen; use it when you *know* based on the function's implementation.